Workbook

Sheet 路线图
A1: 阶段 | B1: 目标 | C1: 关键产出 | D1: 预估工时(周)* | E1: 可并行阶段 | F1: 备注
A2: P0 需求冻结 | B2: 把本次设计对话的内容整理成正式、可执行的文档基线 | C2: 门派/反派机制/数值系统/案件顺序钩子/开篇流程 五份设计文档定稿 | D2: 1 | E2: - | F2: 已基本完成,此阶段主要是整理归档,不是重新设计
A3: P1 核心系统原型 | B3: 用最简单的内容验证核心循环能跑通 | C3: 案0(教学案)全流程可玩:调查→交锋失败→诊断→造梦→结局 | D3: 4 | E3: - | F3: 先证明架构可行,再往复杂内容里投入美术/文案精力
A4: P2 内容数据化 | B4: 把已写好的剧本转换成引擎可读的结构化数据 | C4: 案0/案1《凶宅·友谊》/案2《过嘴瘾》完整数据化,含存档状态旗标设计 | D4: 3 | E4: 可与P1收尾并行 | F4: 凶宅·友谊剧本量最大(五门派结局+发丝共振+三次死局蒙太奇)
A5: P3 美术管线 | B5: 搭建demo范围内的全部美术资产 | C5: 3门派精修人设、案0/案1/案2场景与角色、UI规范、法术特效 | D5: 9 | E5: 与P4全程并行 | F5: 全计划里最大的产能瓶颈,建议评估是否需要外包
A6: P4 系统深化 | B6: 把心魔值/先机道具/门派养成/本地化等系统接入主循环 | C6: 心魔值三阶段反馈、先机道具经济、门派熟练度、双语本地化框架落地 | D6: 4 | E6: 与P3全程并行 | F6: 本地化技术方案已定(Unity Localization),此阶段是集成工作
A7: P5 整合打磨 | B7: 把所有系统和内容串成完整可玩demo | C7: 序章→案0→案1→案2 完整可玩、音效音乐接入、移动端性能优化 | D7: 3 | E7: - | F7: 对应设计文档里'开篇几小时'流程
A8: P6 测试与发布准备 | B8: 验证demo质量,准备对外(测试玩家/发行商)展示 | C8: 内测反馈迭代、双语文本校对、商店素材 | D8: 2 | E8: - | F8: 完成后即达成'验证demo'里程碑,可用于找发行/测试市场反应
A10: * 假设:业余/兼职开发,约每周10-15小时投入;若为全职团队,工时估算需按人力重新折算。
A11: P1-P6 合计约 26 周(~6个月),目标是3案可玩demo,而非完整第一季(8-12案)。

Sheet 任务清单
A1: ID | B1: 阶段 | C1: 类别 | D1: 任务 | E1: 优先级 | F1: 预估工时(h) | G1: 依赖任务ID | H1: 状态 | I1: 备注
A2: T001 | B2: P0 | C2: 文档 | D2: 整理七门派机制表/反派八类型表/数值系统为正式设计文档 | E2: P0 | F2: 4 | H2: 未开始 | I2: 已有初稿,需排版归档
A3: T002 | B3: P0 | C3: 文档 | D3: 新写案0(教学案)完整大纲与台词 | E3: P0 | F3: 4 | H3: 未开始 | I3: 单层执念,轻量语气,20分钟体量
A4: T003 | B4: P0 | C4: 文档 | D4: 定稿术语表(七门派/反派名/核心数值 中英对照) | E4: P0 | F4: 3 | H4: 未开始 | I4: 后续所有翻译强制引用此表
A5: T004 | B5: P0 | C5: 文档 | D5: 定稿开篇几小时流程文档为可执行关卡设计稿 | E5: P1 | F5: 3 | G5: T002 | H5: 未开始
A6: T101 | B6: P1 | C6: 程序 | D6: 搭建Unity项目结构与场景框架 | E6: P0 | F6: 8 | H6: 未开始 | I6: 场景/Prefab/程序集划分
A7: T102 | B7: P1 | C7: 程序 | D7: 实现对话系统基础(文本显示+分支选项) | E7: P0 | F7: 16 | G7: T101 | H7: 未开始 | I7: 可用简化版,先不依赖Localization
A8: T103 | B8: P1 | C8: 程序 | D8: 实现识破值/共鸣值/幻境可信度计算引擎 | E8: P0 | F8: 20 | G8: T101 | H8: 未开始 | I8: 核心公式:见造梦渡化判定文档
A9: T104 | B9: P1 | C9: 程序 | D9: 实现调查/线索收集与线索完整度追踪 | E9: P0 | F9: 12 | G9: T101 | H9: 未开始
A10: T105 | B10: P1 | C10: 程序 | D10: 用案0跑通完整循环并做单元测试 | E10: P0 | F10: 16 | G10: T102,T103,T104,T002 | H10: 未开始 | I10: 验证:调查→交锋失败→诊断→造梦→结局
A11: T106 | B11: P1 | C11: 程序 | D11: 法器反馈系统雏形(符箓/念珠等趋势提示UI) | E11: P1 | F11: 10 | G11: T103 | H11: 未开始 | I11: 先做1个门派版本验证交互
A12: T201 | B12: P2 | C12: 文案 | D12: 案0台词数据结构化(JSON) | E12: P0 | F12: 4 | G12: T002,T105 | H12: 未开始
A13: T202 | B13: P2 | C13: 文案 | D13: 《凶宅·友谊》完整脚本数据化(五门派结局) | E13: P0 | F13: 24 | G13: T105 | H13: 未开始 | I13: 量最大,建议拆五个子任务按门派分头进行
A14: T203 | B14: P2 | C14: 文案 | D14: 三次死局循环蒙太奇过场文案与分镜脚本 | E14: P0 | F14: 6 | G14: T202 | H14: 未开始 | I14: 控制在30秒内的过场
A15: T204 | B15: P2 | C15: 文案 | D15: 发丝共振场景过场文案(婉婉台词/紫苏反应/门派对比画面) | E15: P0 | F15: 4 | G15: T202 | H15: 未开始 | I15: 已有初稿,需转分镜脚本
A16: T205 | B16: P2 | C16: 文案 | D16: 《过嘴瘾》完整脚本数据化(六人链条+四门派断链) | E16: P1 | F16: 16 | G16: T105 | H16: 未开始
A17: T206 | B17: P2 | C17: 程序 | D17: 案件/NPC状态旗标系统(如首领净化/黑化分支追踪) | E17: P0 | F17: 10 | G17: T105 | H17: 未开始 | I17: 为后续《归局》等钩子案预留接口
A18: T207 | B18: P2 | C18: 程序 | D18: 存档系统实现 | E18: P0 | F18: 12 | G18: T206 | H18: 未开始
A19: T301 | B19: P3 | C19: 美术 | D19: 美术风格指南定稿(玄幻唯美,色彩/材质规范) | E19: P0 | F19: 8 | H19: 未开始
A20: T302 | B20: P3 | C20: 美术 | D20: 七门派×2性别人设草图(14套) | E20: P0 | F20: 40 | G20: T301 | H20: 未开始 | I20: 优先精修demo涉及的3-5个门派
A21: T303 | B21: P3 | C21: 美术 | D21: 案0简单反派人设 | E21: P1 | F21: 6 | G21: T301,T002 | H21: 未开始
A22: T304 | B22: P3 | C22: 美术 | D22: 紫苏/婉婉/林家角色人设 | E22: P0 | F22: 20 | G22: T301 | H22: 未开始
A23: T305 | B23: P3 | C23: 美术 | D23: 凶宅别墅场景美术(内外) | E23: P0 | F23: 24 | G23: T301 | H23: 未开始
A24: T306 | B24: P3 | C24: 美术 | D24: 五种幻境结局差异化场景(道士/和尚/阴阳风水/驱魔师/巫师) | E24: P0 | F24: 30 | G24: T305 | H24: 未开始 | I24: 可按优先级先做2-3种再补齐
A25: T307 | B25: P3 | C25: 美术 | D25: 《过嘴瘾》场景与六位NPC人设 | E25: P1 | F25: 20 | G25: T301 | H25: 未开始
A26: T308 | B26: P3 | C26: 美术 | D26: UI关键界面视觉(对话框/案件选择/门派养成) | E26: P0 | F26: 20 | G26: T301 | H26: 未开始
A27: T309 | B27: P3 | C27: 美术 | D27: 法术特效与造梦转场动效 | E27: P1 | F27: 16 | G27: T301 | H27: 未开始
A28: T401 | B28: P4 | C28: 程序 | D28: 心魔值三阶段系统与法器示警UI接入 | E28: P0 | F28: 16 | G28: T106 | H28: 未开始
A29: T402 | B29: P4 | C29: 程序 | D29: 先机道具系统(获取/案内配额/灵机值转化) | E29: P1 | F29: 12 | G29: T206 | H29: 未开始
A30: T403 | B30: P4 | C30: 程序 | D30: 门派熟练度养成系统 | E30: P1 | F30: 10 | G30: T206 | H30: 未开始
A31: T404 | B31: P4 | C31: 程序 | D31: Unity Localization集成(接入已给出的Helper/KeyGenerator框架) | E31: P0 | F31: 10 | G31: T102 | H31: 未开始 | I31: 代码框架已产出,此任务是接入主流程
A32: T405 | B32: P4 | C32: 文案 | D32: 案0/案1/案2文本英文翻译 | E32: P0 | F32: 20 | G32: T201,T202,T203,T204,T003 | H32: 未开始 | I32: 先中文定稿,术语表先行
A33: T406 | B33: P4 | C33: 程序 | D33: 世界善恶值全局系统 | E33: P2 | F33: 8 | G33: T206 | H33: 未开始 | I33: demo阶段可简化为单案内小范围演示
A34: T501 | B34: P5 | C34: 整合 | D34: 序章→案0→案1→案2完整串联测试 | E34: P0 | F34: 16 | G34: T105,T202,T205,T306,T404 | H34: 未开始
A35: T502 | B35: P5 | C35: 音频 | D35: BGM/关键情绪节点音效接入 | E35: P1 | F35: 12 | G35: T501 | H35: 未开始 | I35: 发丝共振等高光时刻优先
A36: T503 | B36: P5 | C36: 程序 | D36: 移动端性能优化(打包/内存/加载) | E36: P0 | F36: 12 | G36: T501 | H36: 未开始
A37: T504 | B37: P5 | C37: 整合 | D37: Bug修复迭代 | E37: P0 | F37: 16 | G37: T501 | H37: 未开始
A38: T601 | B38: P6 | C38: 测试 | D38: 内测(5-10名玩家完整体验demo) | E38: P0 | F38: 8 | G38: T504 | H38: 未开始
A39: T602 | B39: P6 | C39: 文案 | D39: 双语文本校对(人工润色AI初翻的情感浓度高段落) | E39: P0 | F39: 8 | G39: T405 | H39: 未开始 | I39: 尤其是渡化独白/发丝共振等台词
A40: T603 | B40: P6 | C40: 发行 | D40: 应用商店素材准备(截图/宣传文案/演示视频) | E40: P1 | F40: 8 | G40: T601 | H40: 未开始
...

Sheet 阶段工时汇总
A1: 阶段 | B1: 任务数 | C1: 预估总工时(h) | D1: 预估总工时(周,按15h/周)
A2: P0 | B2: =COUNTIF(任务清单!B2:B41,A2) -> 4 | C2: =SUMIF(任务清单!B2:B41,A2,任务清单!F2:F41) -> 14 | D2: =C2/15 -> 0.93333333
A3: P1 | B3: =COUNTIF(任务清单!B2:B41,A3) -> 6 | C3: =SUMIF(任务清单!B2:B41,A3,任务清单!F2:F41) -> 82 | D3: =C3/15 -> 5.4666667
A4: P2 | B4: =COUNTIF(任务清单!B2:B41,A4) -> 7 | C4: =SUMIF(任务清单!B2:B41,A4,任务清单!F2:F41) -> 76 | D4: =C4/15 -> 5.0666667
A5: P3 | B5: =COUNTIF(任务清单!B2:B41,A5) -> 9 | C5: =SUMIF(任务清单!B2:B41,A5,任务清单!F2:F41) -> 184 | D5: =C5/15 -> 12.266667
A6: P4 | B6: =COUNTIF(任务清单!B2:B41,A6) -> 6 | C6: =SUMIF(任务清单!B2:B41,A6,任务清单!F2:F41) -> 76 | D6: =C6/15 -> 5.0666667
A7: P5 | B7: =COUNTIF(任务清单!B2:B41,A7) -> 4 | C7: =SUMIF(任务清单!B2:B41,A7,任务清单!F2:F41) -> 56 | D7: =C7/15 -> 3.7333333
A8: P6 | B8: =COUNTIF(任务清单!B2:B41,A8) -> 4 | C8: =SUMIF(任务清单!B2:B41,A8,任务清单!F2:F41) -> 36 | D8: =C8/15 -> 2.4
A9: 合计 | B9: =SUM(B2:B8) -> 40 | C9: =SUM(C2:C8) -> 524 | D9: =SUM(D2:D8) -> 34.933333
